Workbook

Sheet Capacidad
A1: XPedia - Capacidad del equipo
A2: 7 integrantes - 14 hs semanales por persona (valor ideal declarado, se reajusta con el velocity real de cada sprint)
A4: Integrante | B4: Rol principal | C4: Capacidad por dia (en horas) | J4: Cap. por semana | K4: Cap. por sprint (18 dias)
C5: Lu | D5: Ma | E5: Mie | F5: Ju | G5: Vi | H5: Sa | I5: Do
A6: Dev 1 | B6: Juego / turno | C6: 1 | D6: 1 | E6: 1 | F6: 2 | G6: 2 | H6: 4 | I6: 3 | J6: =SUM(C6:I6) | K6: =ROUND(J6*$C$21/7,1)
A7: Dev 2 | B7: Juego / dialogo | C7: 1 | D7: 1 | E7: 1 | F7: 2 | G7: 2 | H7: 4 | I7: 3 | J7: =SUM(C7:I7) | K7: =ROUND(J7*$C$21/7,1)
A8: Dev 3 | B8: Juego / eventos | C8: 1 | D8: 1 | E8: 1 | F8: 2 | G8: 2 | H8: 4 | I8: 3 | J8: =SUM(C8:I8) | K8: =ROUND(J8*$C$21/7,1)
A9: Dev 4 | B9: UX-UI y arte | C9: 1 | D9: 1 | E9: 1 | F9: 2 | G9: 2 | H9: 4 | I9: 3 | J9: =SUM(C9:I9) | K9: =ROUND(J9*$C$21/7,1)
A10: Dev 5 | B10: Taller de misiones | C10: 1 | D10: 1 | E10: 1 | F10: 2 | G10: 2 | H10: 4 | I10: 3 | J10: =SUM(C10:I10) | K10: =ROUND(J10*$C$21/7,1)
A11: Dev 6 | B11: Admin y progresion | C11: 1 | D11: 1 | E11: 1 | F11: 2 | G11: 2 | H11: 4 | I11: 3 | J11: =SUM(C11:I11) | K11: =ROUND(J11*$C$21/7,1)
A12: Dev 7 | B12: Producto y datos | C12: 1 | D12: 1 | E12: 1 | F12: 2 | G12: 2 | H12: 4 | I12: 3 | J12: =SUM(C12:I12) | K12: =ROUND(J12*$C$21/7,1)
A13: Capacidad de equipo (ideal) | C13: =SUM(C6:C12) | D13: =SUM(D6:D12) | E13: =SUM(E6:E12) | F13: =SUM(F6:F12) | G13: =SUM(G6:G12) | H13: =SUM(H6:H12) | I13: =SUM(I6:I12) | J13: =SUM(J6:J12) | K13: =SUM(K6:K12)
A15: Capacidad NETA por sprint (descontado el factor de no planificados) | K15: =ROUND(K13*(1-C22),0)
A16: Capacidad NETA total del proyecto (4 sprints) | K16: =K15*C20
A19: Variables:
A20: Cantidad de sprints (= 1 MVP por sprint) | C20: 4
A21: Dias por sprint | C21: 18
A22: Factor de dedicacion - No planificados | C22: 0.15
A24: Calendario de sprints
A25: Sprint | B25: MVP | C25: Inicio | D25: Fin | E25: Duracion (dias)
A26: Sprint-Nro1 | B26: MVP 1 | C26: 46289 | D26: 46306 | E26: 18
A27: Sprint-Nro2 | B27: MVP 2 | C27: 46307 | D27: 46324 | E27: 18
A28: Sprint-Nro3 | B28: MVP 3 | C28: 46325 | D28: 46342 | E28: 18
A29: Sprint-Nro4 | B29: MVP 4 | C29: 46343 | D29: 46360 | E29: 18
A30: La ultima entrega (MVP 4) cae el 04/12/2026.

Sheet Product Backlog
A1: XPedia - Product Backlog | D1: Prioridad: 1 = critico para la tesis | 2 = importante | 3 = deseable. Ordenado por lo que mas reduce incertidumbre primero.
A2: #PBI (Historia) | B2: Seccion / Epica (Walking Skeleton) | C2: Nombre | D2: Descripcion | E2: Prioridad | F2: Estimacion (Hs) | G2: Complejidad | H2: Observaciones | I2: Como probarlo? | J2: Sprint
A3: 1.0 | B3: 0 - Definicion de producto | C3: Idea cerrada y defensa de la tesis | D3: Como equipo queremos tener la definicion de producto cerrada por escrito para poder defender la tesis y que ninguna decision posterior la contradiga | E3: 1 | F3: 12 | G3: Media | H3: Consolida vision, no negociables y el giro 4.7 (de 4 minijuegos a un turno de trabajo). Incluye cerrar las 5 preguntas abiertas del documento. | I3: Abrir docs/producto-y-backlog.md y verificar que: (1) las 5 preguntas abiertas de la seccion 6.3 tienen decision escrita con fecha, (2) los 5 no negociables estan enunciados, (3) la bitacora de cambios de rumbo incluye el giro al turno. | J3: Sprint-Nro1
A4: 2.0 | B4: 0 - Definicion de producto | C4: Guion del turno de trabajo | D4: Como disenador de contenido quiero el guion del turno de la sucursal Telecom Sur para poder mockear pantallas sobre un contenido concreto y no inventado | E4: 1 | F4: 14 | G4: Alta | H4: Es el insumo de todos los mocks del juego. Define estaciones, tareas, duraciones en segundos, catalogo de eventos y la tabla atajo -> consecuencia diferida. | I4: Revisar el documento de guion y confirmar que cada estacion tiene tareas con duracion en segundos, que hay al menos 8 eventos catalogados con su frecuencia, y que existen al menos 5 filas de 'atajo -> costo diferido' (ej: no verificaste identidad -> vuelve rebotado a los 2 min). | J4: Sprint-Nro1
A5: 3.0 | B5: 0 - Definicion de producto | C5: Sistema de diseno de XPedia (UI kit) | D5: Como equipo queremos un UI kit unico para que los 12 mocks se vean como un mismo producto y no como 12 prototipos sueltos | E5: 1 | F5: 16 | G5: Media | H5: Debe cumplir las decisiones de UX de la seccion 4.8: tonos claros, sin mayusculas persistentes, texto a izquierda, pastillas de stats sin etiquetas, poco texto. | I5: Abrir el archivo del UI kit y verificar que define paleta en tonos claros (sin modo oscuro), tipografia, y los componentes pastilla de stat, boton, panel de ayuda y modal. Tomar dos mocks cualquiera y confirmar que usan los mismos tokens. | J5: Sprint-Nro1
A6: 4.0 | B6: 1 - Turno de trabajo | C6: Mock del HUD del turno | D6: Como empleado quiero ver el estado completo de mi turno de un vistazo para poder decidir que atiendo primero | E6: 1 | F6: 20 | G6: Alta | H6: Pantalla madre del MVP: mapa de la sucursal con estaciones, cola de clientes, reloj del turno, medidores de paciencia y estres, pastillas de stats. Todo hardcodeado. | I6: Abrir el mock del HUD y verificar: mapa con al menos 4 estaciones senalizadas, cola con al menos 3 clientes esperando, reloj del turno visible, medidores de paciencia por cliente y estres propio, y la fila de pastillas (Lvl, XP %, casos resueltos, habilidad) sin etiquetas de texto. | J6: Sprint-Nro1
A7: 5.0 | B7: 1 - Turno de trabajo | C7: Mock del evento 'Dialogo con consecuencias' | D7: Como empleado quiero atender a un cliente difícil viendo que los demas siguen esperando para sentir el costo real de la conversacion | E7: 1 | F7: 18 | G7: Alta | H7: La diferencia con el prototipo actual es que la cola queda visible detras del panel de dialogo y sigue avanzando. Cada respuesta tiene reaccion visible en el momento (no negociable 1). | I7: Abrir el mock, iniciar el dialogo y verificar: (1) la cola y el reloj siguen visibles y en movimiento detras del panel, (2) cada opcion elegida produce un cambio visible inmediato en el gesto o el medidor de paciencia del cliente, (3) al cerrar el evento aparece el feedback por rubrica y no un 'correcto/incorrecto'. | J7: Sprint-Nro1
A8: 6.0 | B8: 1 - Turno de trabajo | C8: Mock del evento 'Auditoria' | D8: Como empleado quiero detectar algo fuera de norma mientras camino y decidir si paro o sigo para que la auditoria sea una decision de costo y no un buscar diferencias | E8: 1 | F8: 14 | G8: Media | H8: El verbo del jugador no es 'elegir de una lista' sino 'parar el turno para arreglar algo'. El costo de parar debe verse en la cola. | I8: Abrir el mock, pasar por la estacion con el hallazgo y verificar que aparece la opcion de parar; al elegir parar, confirmar que el reloj corre y la cola crece; al elegir seguir, confirmar que queda registrado como atajo en el panel de cierre. | J8: Sprint-Nro1
A9: 7.0 | B9: 1 - Turno de trabajo | C9: Mock del evento 'Ronda / procedimiento' | D9: Como empleado quiero ejecutar un procedimiento paso por paso ocupando tiempo real para que saber el protocolo me haga eficiente y no me de puntos | E9: 1 | F9: 14 | G9: Media | H9: Cada paso ocupa segundos reales. Saltear un paso no da error inmediato: dispara una consecuencia diferida. | I9: Abrir el mock, ejecutar la ronda completa y anotar el tiempo total; repetir salteando un paso y verificar que (1) el turno termina antes, (2) mas tarde aparece la consecuencia diferida asociada a ese paso salteado. | J9: Sprint-Nro1
A10: 8.0 | B10: 1 - Turno de trabajo | C10: Mock del evento 'Crisis' | D10: Como empleado quiero enfrentar una caida de sistema con la cola llena para poder practicar la coordinacion bajo presion | E10: 2 | F10: 12 | G10: Media | H10: Presion por acumulacion, no por reflejos (decision de la pregunta abierta #1). Sin mecanicas de precision ni de apuntar. | I10: Abrir el mock, disparar la crisis y verificar que hay un timer visible, que la cola sigue creciendo durante la crisis, y que las decisiones de coordinacion disponibles son al menos 3 y cambian el estado de la sucursal de forma visible. | J10: Sprint-Nro1
A11: 9.0 | B11: 1 - Turno de trabajo | C11: Mock del cierre de turno: score, record y atajos cobrados | D11: Como empleado quiero ver como me fue al terminar el turno y cuanto me costaron mis atajos para poder querer superar mi propio record | E11: 1 | F11: 14 | G11: Media | H11: Es el motor de rejugabilidad. Debe mostrar el score, el record personal anterior y el detalle de que atajos tome y cuanto tiempo me costaron. | I11: Terminar un turno en el mock y verificar que la pantalla de cierre muestra: score del turno, record personal anterior, cantidad de casos resueltos, y una lista de atajos tomados con el costo en segundos de cada uno. | J11: Sprint-Nro1
A12: 10.0 | B12: 2 - Taller de misiones | C12: Mock del Taller: carga de documentos, clasificacion y brief | D12: Como equipo de contenidos quiero subir la documentacion de la empresa y obtener un brief del caso para poder arrancar la creacion de la mision | E12: 1 | F12: 16 | G12: Media | H12: Carga simulada. Debe incluir la clasificacion doble de la decision 4.3: tipo de contenido (sugerido por IA) y sensibilidad (siempre marcada a mano por el funcional). | I12: Abrir el mock del Taller, simular la carga de un documento y verificar: (1) el sistema sugiere un tipo de contenido, (2) la sensibilidad aparece como alerta sugerida pero requiere marcado manual explicito, (3) se genera un brief con rol, habilidad y situacion. | J12: Sprint-Nro1
A13: 11.0 | B13: 2 - Taller de misiones | C13: Mock del editor de mision de turno + estados de publicacion | D13: Como revisor de contenidos quiero editar la mision generada y publicarla para que nada llegue a un empleado real sin revision humana | E13: 1 | F13: 14 | G13: Media | H13: Cambio respecto del Taller actual: ya no se edita un arbol de dialogo sino el contenido de un turno (estaciones, tareas, duraciones, eventos). Estados: Borrador -> Generado por IA (sin revisar) -> Editado -> Publicado. | I13: Abrir el editor, modificar la duracion de una tarea y el texto de un evento, y verificar que el estado de la mision pasa de 'Generado por IA (sin revisar)' a 'Editado'. Intentar publicar sin revisar y confirmar que el sistema lo bloquea. | J13: Sprint-Nro1
A14: 12.0 | B14: 3 - Vista de admin | C14: Mock de la vista de admin priorizada por 'necesita atencion' | D14: Como lider de L&D quiero ver a quien tengo que ayudar y en que para poder actuar sin micro-gestionar | E14: 2 | F14: 14 | G14: Media | H14: Resuelve la pregunta abierta #3 (agregados vs. individual). No es una tabla plana: la vista se ordena por urgencia de intervencion. | I14: Abrir el mock y verificar que (1) lo primero que se ve es un bloque de 'necesita atencion' con personas o temas concretos y una accion sugerida, (2) no se expone el detalle conversacion por conversacion de cada simulacion, (3) el dato mostrado permite actuar y no es un 'completo / no completo'. | J14: Sprint-Nro1
... A48: 46.0 | B48: 0 - Definicion de producto | C48: Informe final y defensa del proyecto | D48: Como equipo queremos el informe final y la defensa armados para poder presentar el proyecto en la ultima entrega | E48: 1 | F48: 20 | G48: Media | H48: Entrega del 04/12/2026. El activo mas valioso para defender el proyecto es la bitacora de cambios de rumbo: por que giramos y con que evidencia. | I48: Revisar que el informe incluya: la tesis, los datos del piloto (aunque sean malos), la bitacora de giros con su justificacion, y el estado real de cada bache. Ensayar la defensa completa cronometrada. | J48: Sprint-Nro4
E49: TOTAL | F49: =SUM(F3:F48)

Sheet Sprint Backlog Nro1
A1: XPedia - Sprint Backlog
A2: MVP 1 - Idea cerrada y todas las pantallas mockeadas. Nada de backend: todo hardcodeado.
D4: SPRINT | E4: INICIO | F4: FIN | G4: DURACION (dias) | I4: J | J4: V | K4: S | L4: D | M4: L | N4: M | O4: X | P4: J | Q4: V | R4: S | S4: D | T4: L | U4: M | V4: X | W4: J | X4: V | Y4: S | Z4: D
D5: Sprint-Nro1 | E5: 46289 | F5: 46306 | G5: 18 | I5: 46289 | J5: 46290 | K5: 46291 | L5: 46292 | M5: 46293 | N5: 46294 | O5: 46295 | P5: 46296 | Q5: 46297 | R5: 46298 | S5: 46299 | T5: 46300 | U5: 46301 | V5: 46302 | W5: 46303 | X5: 46304 | Y5: 46305 | Z5: 46306
F6: Tareas pendientes | I6: =COUNTIF(I10:I65,">0") | J6: =COUNTIF(J10:J65,">0") | K6: =COUNTIF(K10:K65,">0") | L6: =COUNTIF(L10:L65,">0") | M6: =COUNTIF(M10:M65,">0") | N6: =COUNTIF(N10:N65,">0") | O6: =COUNTIF(O10:O65,">0") | P6: =COUNTIF(P10:P65,">0") | ... Z6: =COUNTIF(Z10:Z65,">0")
F7: Esfuerzo de trabajo pendiente | I7: =SUM(I10:I65) | J7: =SUM(J10:J65) | K7: =SUM(K10:K65) | L7: =SUM(L10:L65) | M7: =SUM(M10:M65) | N7: =SUM(N10:N65) | O7: =SUM(O10:O65) | P7: =SUM(P10:P65) | ... Z7: =SUM(Z10:Z65)
A8: PILA DEL SPRINT Sprint-Nro1 | I8: ESFUERZO PENDIENTE POR DIA (Hs)
A9: #PBI | B9: Tarea | E9: Tipo | F9: Responsable | G9: Estado | H9: Hs x Tarea
A10: 1.0 | B10: Idea cerrada y defensa de la tesis (Definicion de producto)
A11: 1.1 | B11: Consolidar vision, no negociables y tesis en un documento unico | E11: Analisis | F11: Dev 7 | G11: Pendiente | H11: 5 | I11: 3 | J11: 1 | K11: 0 | L11: 0 | M11: 0 | N11: 0 | O11: 0 | P11: 0 | Q11: 0 | R11: 0 | S11: 0 | T11: 0 | U11: 0 | V11: 0 | W11: 0 | X11: 0 | Y11: 0 | Z11: 0
A12: 1.2 | B12: Cerrar por escrito las 5 preguntas abiertas de la seccion 6.3 | E12: Analisis | F12: Dev 7 | G12: Pendiente | H12: 4 | I12: 4 | J12: 4 | K12: 1 | L12: 0 | M12: 0 | N12: 0 | O12: 0 | P12: 0 | Q12: 0 | R12: 0 | S12: 0 | T12: 0 | U12: 0 | V12: 0 | W12: 0 | X12: 0 | Y12: 0 | Z12: 0
A13: 1.3 | B13: Actualizar la bitacora de cambios de rumbo | E13: Documentacion | F13: Dev 7 | G13: Pendiente | H13: 3 | I13: 3 | J13: 3 | K13: 3 | L13: 1 | M13: 0 | N13: 0 | O13: 0 | P13: 0 | Q13: 0 | R13: 0 | S13: 0 | T13: 0 | U13: 0 | V13: 0 | W13: 0 | X13: 0 | Y13: 0 | Z13: 0
A14: 2.0 | B14: Guion del turno de trabajo (Definicion de producto)
A15: 2.1 | B15: Definir estaciones, tareas y duraciones en segundos | E15: Analisis | F15: Dev 3 | G15: Pendiente | H15: 5 | I15: 3 | J15: 1 | K15: 0 | L15: 0 | M15: 0 | N15: 0 | O15: 0 | P15: 0 | Q15: 0 | R15: 0 | S15: 0 | T15: 0 | U15: 0 | V15: 0 | W15: 0 | X15: 0 | Y15: 0 | Z15: 0
A16: 2.2 | B16: Definir el catalogo de eventos y su frecuencia | E16: Analisis | F16: Dev 3 | G16: Pendiente | H16: 5 | I16: 5 | J16: 5 | K16: 2 | L16: 0 | M16: 0 | N16: 0 | O16: 0 | P16: 0 | Q16: 0 | R16: 0 | S16: 0 | T16: 0 | U16: 0 | V16: 0 | W16: 0 | X16: 0 | Y16: 0 | Z16: 0
A17: 2.3 | B17: Definir la tabla atajo -> consecuencia diferida | E17: Analisis | F17: Dev 3 | G17: Pendiente | H17: 4 | I17: 4 | J17: 4 | K17: 4 | L17: 3 | M17: 2 | N17: 1 | O17: 0 | P17: 0 | Q17: 0 | R17: 0 | S17: 0 | T17: 0 | U17: 0 | V17: 0 | W17: 0 | X17: 0 | Y17: 0 | Z17: 0
A18: 3.0 | B18: Sistema de diseno de XPedia (UI kit)
A19: 3.1 | B19: Paleta en tonos claros, tipografia y reglas de texto | E19: Diseno | F19: Dev 4 | G19: Pendiente | H19: 5 | I19: 3 | J19: 1 | K19: 0 | L19: 0 | M19: 0 | N19: 0 | O19: 0 | P19: 0 | Q19: 0 | R19: 0 | S19: 0 | T19: 0 | U19: 0 | V19: 0 | W19: 0 | X19: 0 | Y19: 0 | Z19: 0
A20: 3.2 | B20: Componentes: pastillas de stats, botones y panel de ayuda | E20: Diseno | F20: Dev 4 | G20: Pendiente | H20: 7 | I20: 7 | J20: 7 | K20: 4 | L20: 1 | M20: 0 | N20: 0 | O20: 0 | P20: 0 | Q20: 0 | R20: 0 | S20: 0 | T20: 0 | U20: 0 | V20: 0 | W20: 0 | X20: 0 | Y20: 0 | Z20: 0
A21: 3.3 | B21: Documentar el UI kit para que lo consuman todos los mocks | E21: Documentacion | F21: Dev 4 | G21: Pendiente | H21: 4 | I21: 4 | J21: 4 | K21: 4 | L21: 4 | M21: 4 | N21: 3 | O21: 2 | P21: 0 | Q21: 0 | R21: 0 | S21: 0 | T21: 0 | U21: 0 | V21: 0 | W21: 0 | X21: 0 | Y21: 0 | Z21: 0
A22: 4.0 | B22: Mock del HUD del turno (Turno de trabajo)
A23: 4.1 | B23: Maquetar el mapa de la sucursal con estaciones senalizadas | E23: Desarrollo | F23: Dev 1 | G23: Pendiente | H23: 7 | I23: 5 | J23: 3 | K23: 0 | L23: 0 | M23: 0 | N23: 0 | O23: 0 | P23: 0 | Q23: 0 | R23: 0 | S23: 0 | T23: 0 | U23: 0 | V23: 0 | W23: 0 | X23: 0 | Y23: 0 | Z23: 0
A24: 4.2 | B24: Maquetar el HUD: cola de clientes, reloj del turno y medidores | E24: Desarrollo | F24: Dev 1 | G24: Pendiente | H24: 7 | I24: 7 | J24: 7 | K24: 6 | L24: 3 | M24: 2 | N24: 1 | O24: 0 | P24: 0 | Q24: 0 | R24: 0 | S24: 0 | T24: 0 | U24: 0 | V24: 0 | W24: 0 | X24: 0 | Y24: 0 | Z24: 0
A25: 4.3 | B25: Maquetar las pastillas de stats y el panel de ayuda integrado | E25: Desarrollo | F25: Dev 2 | G25: Pendiente | H25: 4 | I25: 2 | J25: 0 | K25: 0 | L25: 0 | M25: 0 | N25: 0 | O25: 0 | P25: 0 | Q25: 0 | R25: 0 | S25: 0 | T25: 0 | U25: 0 | V25: 0 | W25: 0 | X25: 0 | Y25: 0 | Z25: 0
A26: 4.4 | B26: Revisar el HUD contra las decisiones de UX de la seccion 4.8 | E26: Testing | F26: Dev 4 | G26: Pendiente | H26: 2 | I26: 2 | J26: 2 | K26: 2 | L26: 2 | M26: 2 | N26: 2 | O26: 2 | P26: 2 | Q26: 0 | R26: 0 | S26: 0 | T26: 0 | U26: 0 | V26: 0 | W26: 0 | X26: 0 | Y26: 0 | Z26: 0
A27: 5.0 | B27: Mock del evento 'Dialogo con consecuencias' (Turno de trabajo)
A28: 5.1 | B28: Maquetar el panel de dialogo con la cola visible detras | E28: Desarrollo | F28: Dev 2 | G28: Pendiente | H28: 7 | I28: 7 | J28: 7 | K28: 3 | L28: 0 | M28: 0 | N28: 0 | O28: 0 | P28: 0 | Q28: 0 | R28: 0 | S28: 0 | T28: 0 | U28: 0 | V28: 0 | W28: 0 | X28: 0 | Y28: 0 | Z28: 0
A29: 5.2 | B29: Hardcodear el arbol de 3 niveles con reaccion visible inmediata | E29: Desarrollo | F29: Dev 2 | G29: Pendiente | H29: 7 | I29: 7 | J29: 7 | K29: 7 | L29: 7 | M29: 6 | N29: 5 | O29: 4 | P29: 2 | Q29: 0 | R29: 0 | S29: 0 | T29: 0 | U29: 0 | V29: 0 | W29: 0 | X29: 0 | Y29: 0 | Z29: 0
A30: 5.3 | B30: Maquetar el feedback por rubrica al cerrar el evento | E30: Desarrollo | F30: Dev 2 | G30: Pendiente | H30: 4 | I30: 4 | J30: 4 | K30: 4 | L30: 4 | M30: 4 | N30: 4 | O30: 4 | P30: 4 | Q30: 4 | R30: 0 | S30: 0 | T30: 0 | U30: 0 | V30: 0 | W30: 0 | X30: 0 | Y30: 0 | Z30: 0
A31: 6.0 | B31: Mock del evento 'Auditoria' (Turno de trabajo)
A32: 6.1 | B32: Maquetar la escena con hallazgos senalables al pasar | E32: Desarrollo | F32: Dev 3 | G32: Pendiente | H32: 7 | I32: 7 | J32: 7 | K32: 7 | L32: 7 | M32: 7 | N32: 7 | O32: 7 | P32: 5 | Q32: 3 | R32: 0 | S32: 0 | T32: 0 | U32: 0 | V32: 0 | W32: 0 | X32: 0 | Y32: 0 | Z32: 0
A33: 6.2 | B33: Hardcodear la decision paro/sigo y su costo visible en la cola | E33: Desarrollo | F33: Dev 3 | G33: Pendiente | H33: 7 | I33: 7 | J33: 7 | K33: 7 | L33: 7 | M33: 7 | N33: 7 | O33: 7 | P33: 7 | Q33: 7 | R33: 6 | S33: 3 | T33: 2 | U33: 1 | V33: 0 | W33: 0 | X33: 0 | Y33: 0 | Z33: 0
A34: 7.0 | B34: Mock del evento 'Ronda / procedimiento' (Turno de trabajo)
A35: 7.1 | B35: Maquetar el checklist de pasos con duracion real por paso | E35: Desarrollo | F35: Dev 1 | G35: Pendiente | H35: 7 | I35: 7 | J35: 7 | K35: 7 | L35: 7 | M35: 7 | N35: 7 | O35: 7 | P35: 5 | Q35: 3 | R35: 0 | S35: 0 | T35: 0 | U35: 0 | V35: 0 | W35: 0 | X35: 0 | Y35: 0 | Z35: 0
A36: 7.2 | B36: Hardcodear el paso salteado y su consecuencia diferida | E36: Desarrollo | F36: Dev 1 | G36: Pendiente | H36: 7 | I36: 7 | J36: 7 | K36: 7 | L36: 7 | M36: 7 | N36: 7 | O36: 7 | P36: 7 | Q36: 7 | R36: 6 | S36: 3 | T36: 2 | U36: 1 | V36: 0 | W36: 0 | X36: 0 | Y36: 0 | Z36: 0
A37: 8.0 | B37: Mock del evento 'Crisis' (Turno de trabajo)
A38: 8.1 | B38: Maquetar la caida de sistema con timer y cola creciendo | E38: Desarrollo | F38: Dev 5 | G38: Pendiente | H38: 7 | I38: 5 | J38: 3 | K38: 0 | L38: 0 | M38: 0 | N38: 0 | O38: 0 | P38: 0 | Q38: 0 | R38: 0 | S38: 0 | T38: 0 | U38: 0 | V38: 0 | W38: 0 | X38: 0 | Y38: 0 | Z38: 0
A39: 8.2 | B39: Hardcodear las 3 decisiones de coordinacion | E39: Desarrollo | F39: Dev 5 | G39: Pendiente | H39: 5 | I39: 5 | J39: 5 | K39: 4 | L39: 1 | M39: 0 | N39: 0 | O39: 0 | P39: 0 | Q39: 0 | R39: 0 | S39: 0 | T39: 0 | U39: 0 | V39: 0 | W39: 0 | X39: 0 | Y39: 0 | Z39: 0
A40: 9.0 | B40: Mock del cierre de turno: score, record y atajos (Turno de trabajo)
A41: 9.1 | B41: Maquetar la pantalla de cierre con score y record personal | E41: Desarrollo | F41: Dev 2 | G41: Pendiente | H41: 6 | I41: 6 | J41: 6 | K41: 6 | L41: 6 | M41: 6 | N41: 6 | O41: 6 | P41: 6 | Q41: 6 | R41: 6 | S41: 3 | T41: 2 | U41: 1 | V41: 0 | W41: 0 | X41: 0 | Y41: 0 | Z41: 0
...

Sheet Resumen por Sprint
A1: XPedia - Carga comprometida vs. capacidad
A3: Sprint | B3: MVP | C3: Objetivo del MVP | D3: Inicio | E3: Fin | F3: PBIs | G3: Hs planificadas | H3: Capacidad neta | I3: % de uso
A4: Sprint-Nro1 | B4: MVP 1 | C4: Idea cerrada y todas las pantallas mockeadas. Presentacion de la propuesta. Nada de backend: todo hardcodeado. | D4: 46289 | E4: 46306 | F4: 15 | G4: 214 | H4: =Capacidad!$K$15 | I4: =ROUND(G4/H4*100,0)&"%"
A5: Sprint-Nro2 | B5: MVP 2 | C5: El turno de trabajo jugable de verdad (el giro 4.7) + esqueleto tecnico del stack + primer test con usuarios reales. | D5: 46307 | E5: 46324 | F5: 11 | G5: 206 | H5: =Capacidad!$K$15 | I5: =ROUND(G5/H5*100,0)&"%"
A6: Sprint-Nro3 | B6: MVP 3 | C6: El Taller productivo: RAG real, generacion de contenido de turno con IA, aprobacion humana, auth y multi-tenant. | D6: 46325 | E6: 46342 | F6: 10 | G6: 210 | H6: =Capacidad!$K$15 | I6: =ROUND(G6/H6*100,0)&"%"
A7: Sprint-Nro4 | B7: MVP 4 | C7: Vista de admin con datos reales, modo sensible implementado, progresion, segundo escenario y piloto para la tesis. | D7: 46343 | E7: 46360 | F7: 10 | G7: 208 | H7: =Capacidad!$K$15 | I7: =ROUND(G7/H7*100,0)&"%"
C8: TOTAL | F8: =SUM(F4:F7) | G8: =SUM(G4:G7) | H8: =Capacidad!$K$16 | I8: =ROUND(G8/H8*100,0)&"%"
A11: Como se leen estos numeros
A12: - El % de uso se calcula contra la capacidad NETA (ya descontado el 15% de no planificados), por eso un 95-100% es sano y no sobrecarga.
A13: - Las 14 hs semanales por persona son el valor ideal declarado. Al cierre de cada sprint se compara con las horas reales y se reajusta la capacidad del sprint siguiente.
A14: - Solo el Sprint 1 tiene la pila desglosada en tareas. Los sprints 2 a 4 se desglosan en su propia planificacion, con el velocity real ya medido.
A15: - El Sprint 4 cierra el 04/12/2026, que es la fecha de la ultima entrega.
